<?xml version="1.0" ?>
<!-- =================================================================================== -->
<!-- |    This document was autogenerated by xacro from iiwa_r820_DH.xacro             | -->
<!-- |    EDITING THIS FILE BY HAND IS NOT RECOMMENDED                                 | -->
<!-- =================================================================================== -->
<robot name="iiwa_r820" xmlns:xacro="http://wiki.ros.org/xacro">
  <!-- link list -->
  <link name="iiwa_base_link">
    <visual>
      <origin rpy="0 0 0" xyz="0 0 0"/>
      <geometry>
        <mesh filename="package://iiwa/meshes/iiwa_r820/visual/base_link.dae"/>
      </geometry>
    </visual>
    <collision>
      <origin rpy="0 0 0" xyz="0 0 0"/>
      <geometry>
        <mesh filename="package://iiwa/meshes/iiwa_r820/collision/base_link.stl"/>
      </geometry>
    </collision>
  </link>
  <link name="iiwa_l1">
    <visual>
      <origin rpy="0 0 0" xyz="0 0 0"/>
      <geometry>
        <mesh filename="package://iiwa/meshes/iiwa_r820/visual/link_1.dae"/>
      </geometry>
    </visual>
    <collision>
      <origin rpy="0 0 0" xyz="0 0 0"/>
      <geometry>
        <mesh filename="package://iiwa/meshes/iiwa_r820/collision/link_1.stl"/>
      </geometry>
    </collision>
  </link>
  <link name="iiwa_l2">
    <visual>
      <origin rpy="-1.5708 0 0" xyz="0 0 0"/>
      <geometry>
        <mesh filename="package://iiwa/meshes/iiwa_r820/visual/link_2.dae"/>
      </geometry>
    </visual>
    <collision>
      <origin rpy="-1.5708 0 0" xyz="0 0 0"/>
      <geometry>
        <mesh filename="package://iiwa/meshes/iiwa_r820/collision/link_2.stl"/>
      </geometry>
    </collision>
  </link>
  <link name="iiwa_l3">
    <visual>
      <origin rpy="0 0 0" xyz="0 0 0"/>
      <geometry>
        <mesh filename="package://iiwa/meshes/iiwa_r820/visual/link_3.dae"/>
      </geometry>
    </visual>
    <collision>
      <origin rpy="0 0 0" xyz="0 0 0"/>
      <geometry>
        <mesh filename="package://iiwa/meshes/iiwa_r820/collision/link_3.stl"/>
      </geometry>
    </collision>
  </link>
  <link name="iiwa_l4">
    <visual>
      <origin rpy="-1.5708 0 0" xyz="0 0 0"/>
      <geometry>
        <mesh filename="package://iiwa/meshes/iiwa_r820/visual/link_4.dae"/>
      </geometry>
    </visual>
    <collision>
      <origin rpy="-1.5708 0 0" xyz="0 0 0"/>
      <geometry>
        <mesh filename="package://iiwa/meshes/iiwa_r820/collision/link_4.stl"/>
      </geometry>
    </collision>
  </link>
  <link name="iiwa_l5">
    <visual>
      <origin rpy="0 0 0" xyz="0 0 0"/>
      <geometry>
        <mesh filename="package://iiwa/meshes/iiwa_r820/visual/link_5.dae"/>
      </geometry>
    </visual>
    <collision>
      <origin rpy="0 0 0" xyz="0 0 0"/>
      <geometry>
        <mesh filename="package://iiwa/meshes/iiwa_r820/collision/link_5.stl"/>
      </geometry>
    </collision>
  </link>
  <link name="iiwa_l6">
    <visual>
      <origin rpy="-1.5708 0 0" xyz="0 0 0"/>
      <geometry>
        <mesh filename="package://iiwa/meshes/iiwa_r820/visual/link_6.dae"/>
      </geometry>
    </visual>
    <collision>
      <origin rpy="-1.5708 0 0" xyz="0 0 0"/>
      <geometry>
        <mesh filename="package://iiwa/meshes/iiwa_r820/collision/link_6.stl"/>
      </geometry>
    </collision>
  </link>
  <link name="iiwa_l7">
    <visual>
      <origin rpy="0 0 0" xyz="0 0 0"/>
      <geometry>
        <mesh filename="package://iiwa/meshes/iiwa_r820/visual/link_7.dae"/>
      </geometry>
    </visual>
    <collision>
      <origin rpy="0 0 0" xyz="0 0 0"/>
      <geometry>
        <mesh filename="package://iiwa/meshes/iiwa_r820/collision/link_7.stl"/>
      </geometry>
    </collision>
  </link>
  <link name="tool0"/>
  <!-- end of link list -->
  <!-- ################################################################# -->
  <!-- joint list -->
  <joint name="iiwa_j1" type="revolute">
    <origin rpy="0 0 0" xyz="0 0 0.36"/>
    <parent link="iiwa_base_link"/>
    <child link="iiwa_l1"/>
    <axis xyz="0 0 1"/>
    <limit effort="10" lower="-2.9668" upper="2.9668" velocity="1.4834"/>
  </joint>
  <joint name="iiwa_j2" type="revolute">
    <origin rpy="1.5708 0 0" xyz="-0.00043624 0 0"/>
    <parent link="iiwa_l1"/>
    <child link="iiwa_l2"/>
    <axis xyz="0 0 1"/>
    <limit effort="9" lower="-2.0942" upper="2.0942" velocity="1.4834"/>
  </joint>
  <joint name="iiwa_j3" type="revolute">
    <origin rpy="-1.5708 0 0" xyz="0 0 0"/>
    <parent link="iiwa_l2"/>
    <child link="iiwa_l3"/>
    <axis xyz="0 0 1"/>
    <limit effort="7" lower="-2.9668" upper="2.9668" velocity="1.7452"/>
  </joint>
  <joint name="iiwa_j4" type="revolute">
    <origin rpy="1.5708 0 0" xyz="0.00043624 0 0.42"/>
    <parent link="iiwa_l3"/>
    <child link="iiwa_l4"/>
    <axis xyz="0 0 1"/>
    <limit effort="6" lower="-2.0942" upper="2.0942" velocity="1.3089"/>
  </joint>
  <joint name="iiwa_j5" type="revolute">
    <origin rpy="-1.5708 0 0" xyz="0 0 0"/>
    <parent link="iiwa_l4"/>
    <child link="iiwa_l5"/>
    <axis xyz="0 0 1"/>
    <limit effort="5" lower="-2.9668" upper="2.9668" velocity="2.2688"/>
  </joint>
  <joint name="iiwa_j6" type="revolute">
    <origin rpy="1.5708 0 0" xyz="0 0 0.4"/>
    <parent link="iiwa_l5"/>
    <child link="iiwa_l6"/>
    <axis xyz="0 0 1"/>
    <limit effort="4" lower="-2.0942" upper="2.0942" velocity="2.356"/>
  </joint>
  <joint name="iiwa_j7" type="revolute">
    <origin rpy="-1.5708 0 0" xyz="0 0 0.126"/>
    <parent link="iiwa_l6"/>
    <child link="iiwa_l7"/>
    <axis xyz="0 0 1"/>
    <limit effort="1" lower="-3.0541" upper="3.0541" velocity="2.356"/>
  </joint>
  <!-- <joint name="${prefix}iiwa_j7-tool0" type="fixed">
      <origin xyz="0 0 0.126" rpy="0 0 0" />
      <parent link="${prefix}iiwa_l7" />
      <child link="${prefix}tool0" />
      <axis xyz="0 0 0" />
    </joint> -->
  <!-- end of joint list -->
  <!-- ROS iiwa_base_link to KUKA $ROBROOT coordinate system transform -->
  <link name="base"/>
  <joint name="iiwa_base_link-base" type="fixed">
    <origin rpy="0 0 0" xyz="0 0 0"/>
    <parent link="iiwa_base_link"/>
    <child link="base"/>
  </joint>
  <link name="base_link"/>
  <joint name="base_link-iiwa_base_link" type="fixed">
    <origin rpy="0 0 0" xyz="0 0 0"/>
    <parent link="iiwa_base_link"/>
    <child link="base_link"/>
  </joint>
</robot>

